Workbook
Name p_bulan: Metode_Catatan!$C$6
Name p_listing_rendah: Metode_Catatan!$C$8
Name p_nilai_besar: Metode_Catatan!$C$7

Sheet Dashboard
B2: Dashboard Ekspor Indonesia 2025 | V2: PERIODE DATA
B3: Ekspor nasional per kode HS (Jan–Nov 2025) dan direktori eksportir terdaftar — seluruh angka dihitung dengan rumus dari sheet data | V3: Jan – Nov 2025
B6: TOTAL EKSPOR NASIONAL (US$ MILIAR) | F6: VOLUME EKSPOR (JUTA TON) | J6: KONSENTRASI TOP 10 KODE HS | N6: EKSPORTIR TERDAFTAR | R6: CAKUPAN KODE HS DI DIREKTORI | V6: LISTING BERESTIMASI TIDAK WAJAR
B7: =Ringkasan!$D$28 -> 234.62961 | F7: =Ringkasan!$D$29 -> 240.12678 | J7: =Ringkasan!$D$34 -> 0.26886351 | N7: =Ringkasan!$D$42 -> 773 | R7: =Ringkasan!$D$46 -> 0.063886857 | V7: =Ringkasan!$D$53 -> 0.27282303
B8: ="Jan–Nov 2025 · "&FIXED(Ringkasan!$D$31,0)&" kode HS aktif" -> Jan–Nov 2025 · 8,202 kode HS aktif | F8: ="Harga rata-rata US$ "&ROUND(Ringkasan!$D$30,2)&" per kg" -> Harga rata-rata US$ 0.96 per kg | J8: ="Top 100 HS = "&ROUND(Ringkasan!$D$36*100,1)&"%"&" dari nilai ekspor" -> Top 100 HS = 65.6% dari nilai ekspor | N8: =FIXED(Ringkasan!$D$43,0)&" listing · "&ROUND(Ringkasan!$D$44,1)&" per perusahaan" -> 3,400 listing · 4.4 per perusahaan | R8: ="Mewakili "&ROUND(Ringkasan!$D$47*100,1)&"%"&" nilai ekspor" -> Mewakili 11.7% nilai ekspor | V8: ="Klaim melebihi ekspor nasional HS-nya" -> Klaim melebihi ekspor nasional HS-nya
B10: TEMUAN UTAMA
B11: Ekspor sangat terkonsentrasi | J11: Direktori belum mewakili ekspor | R11: Estimasi pendapatan menyesatkan
B12: ="Top 10 HS = "&ROUND(Ringkasan!$D$34*100,1)&"%"&" nilai ekspor; Top 100 = "&ROUND(Ringkasan!$D$36*100,1)&"%"&". Bab terbesar: "&Ringkasan!$D$32&" ("&ROUND(Ringkasan!$D$33*100,1)&"%"&"). Barang < US$ 1/kg = "&ROUND(Ringkasan!$D$39*100,0)&"% volume tetapi hanya "&ROUND(Ringkasan!$D$38*100,0)&"% nilai." -> Top 10 HS = 26.9% nilai ekspor; Top 100 = 65.6%. Bab terbesar: 15 · Lemak & minyak nabati/hewani (13%). Barang < US$ 1/kg = 72% volume tetapi hanya 18% nilai. | J12: ="Hanya "&FIXED(Ringkasan!$D$45,0)&" dari "&FIXED(Ringkasan!$D$31,0)&" kode HS aktif ada di direktori (≈"&ROUND(Ringkasan!$D$47*100,1)&"%"&" nilai ekspor). "&FIXED(Ringkasan!$D$49,0)&" HS bernilai besar belum punya listing, senilai "&ROUND(Ringkasan!$D$50*100,1)&"%"&" ekspor nasional." -> Hanya 524 dari 8,202 kode HS aktif ada di direktori (≈11.7% nilai ekspor). 1,187 HS bernilai besar belum punya listing, senilai 85.7% ekspor nasional. | R12: =FIXED(Ringkasan!$D$52,0)&" listing ("&ROUND(Ringkasan!$D$53*100,1)&"%"&") mengklaim pendapatan di atas ekspor nasional HS-nya dan menyumbang "&ROUND(Ringkasan!$D$56*100,0)&"% total estimasi. Yang wajar hanya US$ "&ROUND(Ringkasan!$D$55,2)&" dari US$ "&ROUND(Ringkasan!$D$54,1)&" miliar/bulan." -> 777 listing (27.3%) mengklaim pendapatan di atas ekspor nasional HS-nya dan menyumbang 95% total estimasi. Yang wajar hanya US$ 0.69 dari US$ 13 miliar/bulan.
B17: ANALISIS EKSPOR NASIONAL
B52: DIREKTORI EKSPORTIR & KUALITAS DATA
B87: 10 KODE HS PRIORITAS: NILAI EKSPOR TINGGI, KETERWAKILAN RENDAH
B88: # | C88: KODE HS | F88: DESKRIPSI | N88: BAB | R88: NILAI FOB (US$ JUTA) | T88: LISTING | V88: STATUS
B89: =Celah_Pasokan!A9 -> 1 | C89: =Celah_Pasokan!B9 -> 72026000 | F89: =Celah_Pasokan!C9 -> Ferro-nickel | N89: =Celah_Pasokan!E9 -> Besi & baja | R89: =Celah_Pasokan!F9 -> 14941.058 | T89: =Celah_Pasokan!H9 -> 0 | V89: =Celah_Pasokan!I9 -> Belum terwakili
B90: =Celah_Pasokan!A10 -> 2 | C90: =Celah_Pasokan!B10 -> 15119037 | F90: =Celah_Pasokan!C10 -> Liquid fractions of palm oil, refined oil, but not chemically modified, with iodine value 55 or more, but less than 60 | N90: =Celah_Pasokan!E10 -> Lemak & minyak nabati/hewani | R90: =Celah_Pasokan!F10 -> 9998.5251 | T90: =Celah_Pasokan!H10 -> 0 | V90: =Celah_Pasokan!I10 -> Belum terwakili
B91: =Celah_Pasokan!A11 -> 3 | C91: =Celah_Pasokan!B11 -> 71131990 | F91: =Celah_Pasokan!C11 -> Articles of other precious metal jewellery (other than its parts), other than of silver, whether or not plated or clad with precious metal | N91: =Celah_Pasokan!E11 -> Mutiara, permata & logam mulia | R91: =Celah_Pasokan!F11 -> 6753.5157 | T91: =Celah_Pasokan!H11 -> 0 | V91: =Celah_Pasokan!I11 -> Belum terwakili
B92: =Celah_Pasokan!A12 -> 4 | C92: =Celah_Pasokan!B12 -> 15119020 | F92: =Celah_Pasokan!C12 -> Refined palm oil | N92: =Celah_Pasokan!E12 -> Lemak & minyak nabati/hewani | R92: =Celah_Pasokan!F12 -> 5248.687 | T92: =Celah_Pasokan!H12 -> 0 | V92: =Celah_Pasokan!I12 -> Belum terwakili
B93: =Celah_Pasokan!A13 -> 5 | C93: =Celah_Pasokan!B13 -> 27021000 | F93: =Celah_Pasokan!C13 -> Lignite, whether or not pulverised, but not agglomerated | N93: =Celah_Pasokan!E13 -> Batubara, migas & bahan bakar | R93: =Celah_Pasokan!F13 -> 5051.5174 | T93: =Celah_Pasokan!H13 -> 0 | V93: =Celah_Pasokan!I13 -> Belum terwakili
B94: =Celah_Pasokan!A14 -> 6 | C94: =Celah_Pasokan!B14 -> 27111100 | F94: =Celah_Pasokan!C14 -> Liquefied, natural gas | N94: =Celah_Pasokan!E14 -> Batubara, migas & bahan bakar | R94: =Celah_Pasokan!F14 -> 4966.8666 | T94: =Celah_Pasokan!H14 -> 0 | V94: =Celah_Pasokan!I14 -> Belum terwakili
B95: =Celah_Pasokan!A15 -> 7 | C95: =Celah_Pasokan!B15 -> 75012000 | F95: =Celah_Pasokan!C15 -> Nickel oxide sinters and other intermediate products; of nickel metallurgy | N95: =Celah_Pasokan!E15 -> Nikel | R95: =Celah_Pasokan!F15 -> 4843.0894 | T95: =Celah_Pasokan!H15 -> 0 | V95: =Celah_Pasokan!I15 -> Belum terwakili
B96: =Celah_Pasokan!A16 -> 8 | C96: =Celah_Pasokan!B16 -> 26030000 | F96: =Celah_Pasokan!C16 -> Copper ores and concentrates | N96: =Celah_Pasokan!E16 -> Bijih, terak & abu logam | R96: =Celah_Pasokan!F16 -> 4545.5013 | T96: =Celah_Pasokan!H16 -> 0 | V96: =Celah_Pasokan!I16 -> Belum terwakili
B97: =Celah_Pasokan!A17 -> 9 | C97: =Celah_Pasokan!B17 -> 87032259 | F97: =Celah_Pasokan!C17 -> Motor cars (including station wagons and sports cars, but not including vans), other than of 4-wheel drive, with only spark-ignition internal combustion piston engine, of a cylinder capacity > 1,000 cc but ≤ 1,500 cc, other than CKD | N97: =Celah_Pasokan!E17 -> Kendaraan bermotor | R97: =Celah_Pasokan!F17 -> 3584.1137 | T97: =Celah_Pasokan!H17 -> 0 | V97: =Celah_Pasokan!I17 -> Belum terwakili
B98: =Celah_Pasokan!A18 -> 10 | C98: =Celah_Pasokan!B18 -> 27011290 | F98: =Celah_Pasokan!C18 -> Bituminous coal, whether or not pulverised, but not agglomerated, other than coking coal | N98: =Celah_Pasokan!E18 -> Batubara, migas & bahan bakar | R98: =Celah_Pasokan!F18 -> 3150.4652 | T98: =Celah_Pasokan!H18 -> 0 | V98: =Celah_Pasokan!I18 -> Belum terwakili
B100: Sumber: HS_Code.csv (ekspor nasional Jan–Nov 2025) dan IndonesiaExportir.csv (direktori eksportir). Parameter dan metode ada di sheet Metode_Catatan; temuan lengkap di sheet Ringkasan.

Sheet Ringkasan
A1: Ringkasan Analisis
A2: Temuan utama, rekomendasi, dan metrik kunci — kalimat temuan dihitung otomatis dari data
B4: TEMUAN UTAMA
B5: 1 | C5: Ekspor sangat terkonsentrasi | D5: ="10 kode HS teratas menyumbang "&ROUND($D$34*100,1)&"%"&" nilai ekspor dan 100 teratas "&ROUND($D$36*100,1)&"%"&", padahal terdapat "&FIXED($D$31,0)&" kode HS aktif. Bab terbesar adalah "&$D$32&" dengan "&ROUND($D$33*100,1)&"%"&" dari total nilai ekspor US$ "&ROUND($D$28,1)&" miliar (Jan–Nov 2025)." -> 10 kode HS teratas menyumbang 26.9% nilai ekspor dan 100 teratas 65.6%, padahal terdapat 8,202 kode HS aktif. Bab terbesar adalah 15 · Lemak & minyak nabati/hewani dengan 13% dari total nilai ekspor US$ 234.6 miliar (Jan–Nov 2025).
B6: 2 | C6: Nilai dan volume bercerita berbeda | D6: ="Barang berharga di bawah US$ 1/kg menyumbang "&ROUND($D$39*100,1)&"%"&" volume tetapi hanya "&ROUND($D$38*100,1)&"%"&" nilai, sedangkan barang ≥ US$ 100/kg hanya "&ROUND($D$41*100,2)&"%"&" volume namun "&ROUND($D$40*100,1)&"%"&" nilai. Nilai ekspor lebih ditentukan oleh komposisi produk bernilai tambah daripada tonase." -> Barang berharga di bawah US$ 1/kg menyumbang 71.7% volume tetapi hanya 18.4% nilai, sedangkan barang ≥ US$ 100/kg hanya 0.01% volume namun 7.4% nilai. Nilai ekspor lebih ditentukan oleh komposisi produk bernilai tambah daripada tonase.
B7: 3 | C7: Direktori hanya mewakili sebagian kecil ekspor | D7: ="Direktori mencakup "&FIXED($D$45,0)&" dari "&FIXED($D$31,0)&" kode HS aktif ("&ROUND($D$46*100,1)&"%"&"), setara "&ROUND($D$47*100,1)&"%"&" nilai ekspor nasional. Dari "&FIXED($D$48,0)&" HS bernilai ≥ US$ "&ROUND(p_nilai_besar/10^6,0)&" juta, "&FIXED($D$49,0)&" belum punya satu pun listing eksportir." -> Direktori mencakup 524 dari 8,202 kode HS aktif (6.4%), setara 11.7% nilai ekspor nasional. Dari 1,308 HS bernilai ≥ US$ 10 juta, 1,187 belum punya satu pun listing eksportir.
B8: 4 | C8: Komposisi direktori condong ke komoditas tertentu | D8: ="Bab '"&$D$68&"' memuat "&ROUND($D$69*100,1)&"%"&" seluruh listing, padahal hanya "&ROUND($D$70*100,1)&"%"&" nilai ekspor nasional. Sebaliknya, di antara 10 bab terbesar, "&$D$71&" paling kurang terwakili: "&ROUND($D$72*100,1)&"%"&" nilai ekspor tetapi hanya "&FIXED($D$73,0)&" listing." -> Bab 'Kopi, teh & rempah' memuat 26.7% seluruh listing, padahal hanya 1.4% nilai ekspor nasional. Sebaliknya, di antara 10 bab terbesar, 75 · Nikel paling kurang terwakili: 3.6% nilai ekspor tetapi hanya 0 listing.
B9: 5 | C9: Celah pasokan terbesar ada pada bab bernilai tinggi | D9: ="Nilai HS yang belum terwakili mencapai "&ROUND($D$50*100,1)&"%"&" ekspor nasional (US$ "&ROUND($D$50*$D$28,1)&" miliar). Bab dengan nilai belum terwakili terbesar: "&Bab_HS!S19&" (US$ "&ROUND(Bab_HS!T19,1)&" miliar), disusul "&Bab_HS!S20&" dan "&Bab_HS!S21&". Daftar 30 HS prioritas ada di sheet Celah_Pasokan." -> Nilai HS yang belum terwakili mencapai 85.7% ekspor nasional (US$ 201.1 miliar). Bab dengan nilai belum terwakili terbesar: 72 · Besi & baja (US$ 24.4 miliar), disusul 15 · Lemak & minyak nabati/hewani dan 27 · Batubara, migas & bahan bakar. Daftar 30 HS prioritas ada di sheet Celah_Pasokan.
B10: 6 | C10: Estimasi pendapatan eksportir tidak bisa dipakai mentah | D10: ="Total estimasi pendapatan mentah US$ "&ROUND($D$54,1)&" miliar/bulan setara "&ROUND($D$54/$D$57*100,0)&"% seluruh ekspor Indonesia per bulan, tidak masuk akal untuk "&FIXED($D$42,0)&" perusahaan. Penyebabnya: "&FIXED($D$52,0)&" listing ("&ROUND($D$53*100,1)&"%"&" dari yang berestimasi) mengklaim pendapatan melebihi total ekspor nasional HS-nya dan menyumbang "&ROUND($D$56*100,1)&"%"&" total estimasi. Harga di direktori hanyalah rata-rata nasional per HS, sehingga salah pilih kode HS langsung membengkakkan angka. Setelah disaring tersisa US$ "&ROUND($D$55,2)&" miliar/bulan." -> Total estimasi pendapatan mentah US$ 13 miliar/bulan setara 61% seluruh ekspor Indonesia per bulan, tidak masuk akal untuk 773 perusahaan. Penyebabnya: 777 listing (27.3% dari yang berestimasi) mengklaim pendapatan melebihi total ekspor nasional HS-nya dan menyumbang 94.6% total estimasi. Harga di direktori hanyalah rata-rata nasional per HS, sehingga salah pilih kode HS langsung membengkakkan angka. Setelah disaring tersisa US$ 0.69 miliar/bulan.
B11: 7 | C11: Eksportir terpusat di Pulau Jawa | D11: =ROUND($D$58*100,1)&"%"&" perusahaan berada di enam provinsi Jawa (DKI Jakarta, Jawa Barat, Jawa Tengah, Jawa Timur, DI Yogyakarta, Banten). Provinsi terbanyak: "&$D$59&" ("&FIXED($D$60,0)&" perusahaan). Perusahaan dengan listing terbanyak: "&$D$61&" ("&FIXED($D$62,0)&" listing)." -> 68.7% perusahaan berada di enam provinsi Jawa (DKI Jakarta, Jawa Barat, Jawa Tengah, Jawa Timur, DI Yogyakarta, Banten). Provinsi terbanyak: Jawa Timur (149 perusahaan). Perusahaan dengan listing terbanyak: ATHAYA AGRO PRATINDO, PT (62 listing).
B12: 8 | C12: Praktik transaksi dan kelengkapan data | D12: ="FOB dipakai pada "&ROUND($D$63*100,1)&"%"&" listing; T/T "&ROUND($D$64*100,1)&"%"&" dan LC "&ROUND($D$65*100,1)&"%"&". Namun pelabuhan ekspor kosong pada "&ROUND($D$66*100,1)&"%"&" listing dan "&FIXED($D$67,0)&" listing berkode HS 00000000, sehingga analisis logistik dan pemetaan produk perlu dilengkapi dulu." -> FOB dipakai pada 69.8% listing; T/T 53.1% dan LC 38.2%. Namun pelabuhan ekspor kosong pada 68.3% listing dan 307 listing berkode HS 00000000, sehingga analisis logistik dan pemetaan produk perlu dilengkapi dulu.
B14: REKOMENDASI
B15: 1 | C15: Mulai skrining dari sheet Celah_Pasokan | D15: Verifikasi apakah eksportir besar pada 30 kode HS prioritas memang tidak memakai direktori. Sisanya dapat dijadikan target rekrutmen eksportir atau pencarian pemasok.
B16: 2 | C16: Jangan pakai estimasi pendapatan mentah | D16: Gunakan hanya listing berstatus 'Wajar' (filter kolom Status estimasi di Data_Eksportir). Minta harga penawaran per perusahaan dan perbaiki pemetaan kode HS pada listing yang melebihi ekspor nasional.
B17: 3 | C17: Perbaiki kualitas data direktori | D17: Lengkapi kode HS 00000000, nama produk kosong, dan pelabuhan ekspor yang belum terisi, serta minimum order/kapasitas agar estimasi volume tidak bergantung pada asumsi.
B18: 4 | C18: Bedakan strategi per bab | D18: Bab berindeks keterwakilan > 1 ramai pemasok relatif terhadap nilai ekspornya, sehingga fokus pada diferensiasi dan pasar baru. Bab bernilai besar berindeks < 1 menunjukkan ruang menambah pemasok terdaftar dan pendampingan ekspor (lihat sheet Bab_HS).
B19: 5 | C19: Pertimbangkan sebaran geografis | D19: Jika tujuannya pemerataan, perluas pembinaan dan onboarding eksportir di luar Jawa (lihat tabel provinsi di sheet Eksportir).
B20: 6 | C20: Perdalam data berikutnya | D20: Tambahkan data bulan/tahun sebelumnya untuk melihat pertumbuhan dan musiman, serta negara tujuan agar peluang pasar lebih tajam. Ubah parameter di Metode_Catatan untuk menguji sensitivitas ambang nilai.
B25: METRIK KUNCI (sumber seluruh angka pada dashboard & temuan)
B27: No | C27: Metrik | D27: Nilai | E27: Satuan
B28: 1 | C28: Total nilai ekspor nasional (Jan–Nov 2025) | D28: =SUM(Data_HS!$D$2:$D$8217)/10^9 -> 234.62961 | E28: USD miliar
B29: 2 | C29: Total volume ekspor (hanya HS yang punya data berat) | D29: =SUM(Data_HS!$C$2:$C$8217)/10^9 -> 240.12678 | E29: juta ton
B30: 3 | C30: Harga rata-rata tertimbang | D30: =SUMIFS(Data_HS!$D$2:$D$8217,Data_HS!$C$2:$C$8217,">0")/SUM(Data_HS!$C$2:$C$8217) -> 0.95607018 | E30: USD/kg
B31: 4 | C31: Jumlah kode HS aktif (nilai > 0) | D31: =COUNTIF(Data_HS!$D$2:$D$8217,">0") -> 8202 | E31: kode HS
B32: 5 | C32: Bab dengan nilai ekspor terbesar | D32: =Bab_HS!S6 -> 15 · Lemak & minyak nabati/hewani
B33: 6 | C33: Pangsa bab terbesar | D33: =Bab_HS!U6 -> 0.13031136 | E33: % nilai
B34: 7 | C34: Pangsa 10 kode HS teratas | D34: =Top_HS!Q6 -> 0.26886351 | E34: % nilai
B35: 8 | C35: Pangsa 50 kode HS teratas | D35: =Top_HS!Q7 -> 0.53665365 | E35: % nilai
B36: 9 | C36: Pangsa 100 kode HS teratas | D36: =Top_HS!Q8 -> 0.65612052 | E36: % nilai
B37: 10 | C37: Pangsa 500 kode HS teratas | D37: =Top_HS!Q9 -> 0.88411341 | E37: % nilai
B38: 11 | C38: Segmen < US$ 1/kg: pangsa nilai | D38: =Top_HS!S15 -> 0.18447282 | E38: % nilai
B39: 12 | C39: Segmen < US$ 1/kg: pangsa volume | D39: =Top_HS!T15 -> 0.71721676 | E39: % volume
B40: 13 | C40: Segmen ≥ US$ 100/kg: pangsa nilai | D40: =Top_HS!S19 -> 0.073711576 | E40: % nilai
B41: 14 | C41: Segmen ≥ US$ 100/kg: pangsa volume | D41: =Top_HS!T19 -> 0.0001112292 | E41: % volume
B42: 15 | C42: Jumlah perusahaan eksportir di direktori | D42: =COUNTA(Profil_Perusahaan!$A$2:$A$774) -> 773 | E42: perusahaan
B43: 16 | C43: Jumlah listing produk | D43: =COUNTA(Data_Eksportir!$B$2:$B$3401) -> 3400 | E43: listing
B44: 17 | C44: Rata-rata listing per perusahaan | D44: =D43/D42 -> 4.3984476 | E44: listing
B45: 18 | C45: Kode HS aktif yang punya ≥ 1 listing | D45: =COUNTIFS(Data_HS!$G$2:$G$8217,">0",Data_HS!$D$2:$D$8217,">0") -> 524 | E45: kode HS
B46: 19 | C46: Cakupan kode HS aktif oleh direktori | D46: =D45/D31 -> 0.063886857 | E46: % kode HS
B47: 20 | C47: Nilai ekspor dari HS yang punya listing | D47: =SUMIFS(Data_HS!$D$2:$D$8217,Data_HS!$G$2:$G$8217,">0")/SUM(Data_HS!$D$2:$D$8217) -> 0.11650167 | E47: % nilai
...

Sheet Bab_HS
A1: Analisis per Bab HS (2 digit)
A2: Ekspor nasional Jan–Nov 2025 vs keterwakilan eksportir di direktori — seluruh sel dihitung dengan rumus
A4: Ringkasan seluruh bab HS | Q4: Top 10 bab menurut nilai ekspor
A5: Bab | B5: Nama bab | C5: Jml HS aktif | D5: Berat (juta ton) | E5: Nilai FOB (USD miliar) | F5: Pangsa nilai | G5: Harga rata-rata (USD/kg) | H5: Listing eksportir | I5: Pangsa listing | J5: Indeks keterwakilan | K5: Jml HS belum terwakili | L5: Nilai HS belum terwakili (USD miliar) | M5: Est. kapasitas wajar (USD juta/bln) | N5: Urut nilai (helper) | O5: Urut celah (helper) | Q5: Peringkat | R5: Baris (helper) | S5: Bab | T5: Nilai FOB (USD miliar) | U5: Pangsa nilai | V5: Pangsa listing | W5: Indeks keterwakilan | X5: Listing
A6: 0 | B6: Tidak terklasifikasi (HS 00000000) | C6: =COUNTIFS(Data_HS!$F$2:$F$8217,A6,Data_HS!$D$2:$D$8217,">0") -> 0 | D6: =SUMIFS(Data_HS!$C$2:$C$8217,Data_HS!$F$2:$F$8217,A6)/10^9 -> 0 | E6: =SUMIFS(Data_HS!$D$2:$D$8217,Data_HS!$F$2:$F$8217,A6)/10^9 -> 0 | F6: =E6/$E$105 -> 0 | G6: =IFERROR(SUMIFS(Data_HS!$D$2:$D$8217,Data_HS!$F$2:$F$8217,A6,Data_HS!$C$2:$C$8217,">0")/SUMIFS(Data_HS!$C$2:$C$8217,Data_HS!$F$2:$F$8217,A6),"") | H6: =COUNTIF(Data_Eksportir!$O$2:$O$3401,A6) -> 307 | I6: =IF(A6=0,"",H6/COUNTIF(Data_Eksportir!$O$2:$O$3401,">0")) | J6: =IF(OR(A6=0,F6=0),"",I6/F6) | K6: =COUNTIFS(Data_HS!$F$2:$F$8217,A6,Data_HS!$I$2:$I$8217,"Belum terwakili") -> 0 | L6: =SUMIFS(Data_HS!$D$2:$D$8217,Data_HS!$F$2:$F$8217,A6,Data_HS!$I$2:$I$8217,"Belum terwakili")/10^9 -> 0 | M6: =SUMIFS(Data_Eksportir!$N$2:$N$3401,Data_Eksportir!$O$2:$O$3401,A6,Data_Eksportir!$Q$2:$Q$3401,"Wajar")/10^6 -> 0 | N6: =E6+ROW()/10^9 -> 6e-09 | O6: =L6+ROW()/10^9 -> 6e-09 | Q6: 1 | R6: =MATCH(LARGE($N$6:$N$104,Q6),$N$6:$N$104,0) -> 16 | S6: =TEXT(INDEX($A$6:$A$104,R6),"00")&" · "&INDEX($B$6:$B$104,R6) -> 15 · Lemak & minyak nabati/hewani | T6: =INDEX($E$6:$E$104,R6) -> 30.574903 | U6: =INDEX($F$6:$F$104,R6) -> 0.13031136 | V6: =INDEX($I$6:$I$104,R6) -> 0.042030391 | W6: =IFERROR(V6/U6,"") -> 0.3225382 | X6: =INDEX($H$6:$H$104,R6) -> 130
A7: 1 | B7: Hewan hidup | C7: =COUNTIFS(Data_HS!$F$2:$F$8217,A7,Data_HS!$D$2:$D$8217,">0") -> 17 | D7: =SUMIFS(Data_HS!$C$2:$C$8217,Data_HS!$F$2:$F$8217,A7)/10^9 -> 0.000394052 | E7: =SUMIFS(Data_HS!$D$2:$D$8217,Data_HS!$F$2:$F$8217,A7)/10^9 -> 0.007975873 | F7: =E7/$E$105 -> 3.3993464e-05 | G7: =IFERROR(SUMIFS(Data_HS!$D$2:$D$8217,Data_HS!$F$2:$F$8217,A7,Data_HS!$C$2:$C$8217,">0")/SUMIFS(Data_HS!$C$2:$C$8217,Data_HS!$F$2:$F$8217,A7),"") -> 20.240661 | H7: =COUNTIF(Data_Eksportir!$O$2:$O$3401,A7) -> 0 | I7: =IF(A7=0,"",H7/COUNTIF(Data_Eksportir!$O$2:$O$3401,">0")) -> 0 | J7: =IF(OR(A7=0,F7=0),"",I7/F7) -> 0 | K7: =COUNTIFS(Data_HS!$F$2:$F$8217,A7,Data_HS!$I$2:$I$8217,"Belum terwakili") -> 0 | L7: =SUMIFS(Data_HS!$D$2:$D$8217,Data_HS!$F$2:$F$8217,A7,Data_HS!$I$2:$I$8217,"Belum terwakili")/10^9 -> 0 | M7: =SUMIFS(Data_Eksportir!$N$2:$N$3401,Data_Eksportir!$O$2:$O$3401,A7,Data_Eksportir!$Q$2:$Q$3401,"Wajar")/10^6 -> 0 | N7: =E7+ROW()/10^9 -> 0.00797588 | O7: =L7+ROW()/10^9 -> 7e-09 | Q7: 2 | R7: =MATCH(LARGE($N$6:$N$104,Q7),$N$6:$N$104,0) -> 73 | S7: =TEXT(INDEX($A$6:$A$104,R7),"00")&" · "&INDEX($B$6:$B$104,R7) -> 72 · Besi & baja | T7: =INDEX($E$6:$E$104,R7) -> 24.775586 | U7: =INDEX($F$6:$F$104,R7) -> 0.10559446 | V7: =INDEX($I$6:$I$104,R7) -> 0.0054962819 | W7: =IFERROR(V7/U7,"") -> 0.052050857 | X7: =INDEX($H$6:$H$104,R7) -> 17
A8: 2 | B8: Daging | C8: =COUNTIFS(Data_HS!$F$2:$F$8217,A8,Data_HS!$D$2:$D$8217,">0") -> 22 | D8: =SUMIFS(Data_HS!$C$2:$C$8217,Data_HS!$F$2:$F$8217,A8)/10^9 -> 0.001825197 | E8: =SUMIFS(Data_HS!$D$2:$D$8217,Data_HS!$F$2:$F$8217,A8)/10^9 -> 0.011658113 | F8: =E8/$E$105 -> 4.9687306e-05 | G8: =IFERROR(SUMIFS(Data_HS!$D$2:$D$8217,Data_HS!$F$2:$F$8217,A8,Data_HS!$C$2:$C$8217,">0")/SUMIFS(Data_HS!$C$2:$C$8217,Data_HS!$F$2:$F$8217,A8),"") -> 6.3873176 | H8: =COUNTIF(Data_Eksportir!$O$2:$O$3401,A8) -> 28 | I8: =IF(A8=0,"",H8/COUNTIF(Data_Eksportir!$O$2:$O$3401,">0")) -> 0.0090526996 | J8: =IF(OR(A8=0,F8=0),"",I8/F8) -> 182.19341 | K8: =COUNTIFS(Data_HS!$F$2:$F$8217,A8,Data_HS!$I$2:$I$8217,"Belum terwakili") -> 0 | L8: =SUMIFS(Data_HS!$D$2:$D$8217,Data_HS!$F$2:$F$8217,A8,Data_HS!$I$2:$I$8217,"Belum terwakili")/10^9 -> 0 | M8: =SUMIFS(Data_Eksportir!$N$2:$N$3401,Data_Eksportir!$O$2:$O$3401,A8,Data_Eksportir!$Q$2:$Q$3401,"Wajar")/10^6 -> 5.9627792e-05 | N8: =E8+ROW()/10^9 -> 0.011658121 | O8: =L8+ROW()/10^9 -> 8e-09 | Q8: 3 | R8: =MATCH(LARGE($N$6:$N$104,Q8),$N$6:$N$104,0) -> 28 | S8: =TEXT(INDEX($A$6:$A$104,R8),"00")&" · "&INDEX($B$6:$B$104,R8) -> 27 · Batubara, migas & bahan bakar | T8: =INDEX($E$6:$E$104,R8) -> 23.823585 | U8: =INDEX($F$6:$F$104,R8) -> 0.101537 | V8: =INDEX($I$6:$I$104,R8) -> 0.010669253 | W8: =IFERROR(V8/U8,"") -> 0.10507749 | X8: =INDEX($H$6:$H$104,R8) -> 33
A9: 3 | B9: Ikan & hasil laut | C9: =COUNTIFS(Data_HS!$F$2:$F$8217,A9,Data_HS!$D$2:$D$8217,">0") -> 245 | D9: =SUMIFS(Data_HS!$C$2:$C$8217,Data_HS!$F$2:$F$8217,A9)/10^9 -> 0.803831 | E9: =SUMIFS(Data_HS!$D$2:$D$8217,Data_HS!$F$2:$F$8217,A9)/10^9 -> 3.5981188 | F9: =E9/$E$105 -> 0.015335315 | G9: =IFERROR(SUMIFS(Data_HS!$D$2:$D$8217,Data_HS!$F$2:$F$8217,A9,Data_HS!$C$2:$C$8217,">0")/SUMIFS(Data_HS!$C$2:$C$8217,Data_HS!$F$2:$F$8217,A9),"") -> 4.4762128 | H9: =COUNTIF(Data_Eksportir!$O$2:$O$3401,A9) -> 59 | I9: =IF(A9=0,"",H9/COUNTIF(Data_Eksportir!$O$2:$O$3401,">0")) -> 0.019075331 | J9: =IF(OR(A9=0,F9=0),"",I9/F9) -> 1.2438826 | K9: =COUNTIFS(Data_HS!$F$2:$F$8217,A9,Data_HS!$I$2:$I$8217,"Belum terwakili") -> 31 | L9: =SUMIFS(Data_HS!$D$2:$D$8217,Data_HS!$F$2:$F$8217,A9,Data_HS!$I$2:$I$8217,"Belum terwakili")/10^9 -> 2.4599276 | M9: =SUMIFS(Data_Eksportir!$N$2:$N$3401,Data_Eksportir!$O$2:$O$3401,A9,Data_Eksportir!$Q$2:$Q$3401,"Wajar")/10^6 -> 5.5478968 | N9: =E9+ROW()/10^9 -> 3.5981188 | O9: =L9+ROW()/10^9 -> 2.4599276 | Q9: 4 | R9: =MATCH(LARGE($N$6:$N$104,Q9),$N$6:$N$104,0) -> 85 | S9: =TEXT(INDEX($A$6:$A$104,R9),"00")&" · "&INDEX($B$6:$B$104,R9) -> 85 · Mesin listrik & elektronik | T9: =INDEX($E$6:$E$104,R9) -> 17.496555 | U9: =INDEX($F$6:$F$104,R9) -> 0.074570959 | V9: =INDEX($I$6:$I$104,R9) -> 0.0077594568 | W9: =IFERROR(V9/U9,"") -> 0.10405467 | X9: =INDEX($H$6:$H$104,R9) -> 24
A10: 4 | B10: Susu, telur & madu | C10: =COUNTIFS(Data_HS!$F$2:$F$8217,A10,Data_HS!$D$2:$D$8217,">0") -> 49 | D10: =SUMIFS(Data_HS!$C$2:$C$8217,Data_HS!$F$2:$F$8217,A10)/10^9 -> 0.055669622 | E10: =SUMIFS(Data_HS!$D$2:$D$8217,Data_HS!$F$2:$F$8217,A10)/10^9 -> 0.51110084 | F10: =E10/$E$105 -> 0.0021783306 | G10: =IFERROR(SUMIFS(Data_HS!$D$2:$D$8217,Data_HS!$F$2:$F$8217,A10,Data_HS!$C$2:$C$8217,">0")/SUMIFS(Data_HS!$C$2:$C$8217,Data_HS!$F$2:$F$8217,A10),"") -> 9.1809649 | H10: =COUNTIF(Data_Eksportir!$O$2:$O$3401,A10) -> 75 | I10: =IF(A10=0,"",H10/COUNTIF(Data_Eksportir!$O$2:$O$3401,">0")) -> 0.024248303 | J10: =IF(OR(A10=0,F10=0),"",I10/F10) -> 11.131599 | K10: =COUNTIFS(Data_HS!$F$2:$F$8217,A10,Data_HS!$I$2:$I$8217,"Belum terwakili") -> 0 | L10: =SUMIFS(Data_HS!$D$2:$D$8217,Data_HS!$F$2:$F$8217,A10,Data_HS!$I$2:$I$8217,"Belum terwakili")/10^9 -> 0 | M10: =SUMIFS(Data_Eksportir!$N$2:$N$3401,Data_Eksportir!$O$2:$O$3401,A10,Data_Eksportir!$Q$2:$Q$3401,"Wajar")/10^6 -> 1.2504402 | N10: =E10+ROW()/10^9 -> 0.51110086 | O10: =L10+ROW()/10^9 -> 1e-08 | Q10: 5 | R10: =MATCH(LARGE($N$6:$N$104,Q10),$N$6:$N$104,0) -> 87 | S10: =TEXT(INDEX($A$6:$A$104,R10),"00")&" · "&INDEX($B$6:$B$104,R10) -> 87 · Kendaraan bermotor | T10: =INDEX($E$6:$E$104,R10) -> 10.862972 | U10: =INDEX($F$6:$F$104,R10) -> 0.046298387 | V10: =INDEX($I$6:$I$104,R10) -> 0.0009699321 | W10: =IFERROR(V10/U10,"") -> 0.020949587 | X10: =INDEX($H$6:$H$104,R10) -> 3
A11: 5 | B11: Produk hewani lainnya | C11: =COUNTIFS(Data_HS!$F$2:$F$8217,A11,Data_HS!$D$2:$D$8217,">0") -> 16 | D11: =SUMIFS(Data_HS!$C$2:$C$8217,Data_HS!$F$2:$F$8217,A11)/10^9 -> 0.02208941 | E11: =SUMIFS(Data_HS!$D$2:$D$8217,Data_HS!$F$2:$F$8217,A11)/10^9 -> 0.039746529 | F11: =E11/$E$105 -> 0.00016940117 | G11: =IFERROR(SUMIFS(Data_HS!$D$2:$D$8217,Data_HS!$F$2:$F$8217,A11,Data_HS!$C$2:$C$8217,">0")/SUMIFS(Data_HS!$C$2:$C$8217,Data_HS!$F$2:$F$8217,A11),"") -> 1.7993477 | H11: =COUNTIF(Data_Eksportir!$O$2:$O$3401,A11) -> 15 | I11: =IF(A11=0,"",H11/COUNTIF(Data_Eksportir!$O$2:$O$3401,">0")) -> 0.0048496605 | J11: =IF(OR(A11=0,F11=0),"",I11/F11) -> 28.628259 | K11: =COUNTIFS(Data_HS!$F$2:$F$8217,A11,Data_HS!$I$2:$I$8217,"Belum terwakili") -> 1 | L11: =SUMIFS(Data_HS!$D$2:$D$8217,Data_HS!$F$2:$F$8217,A11,Data_HS!$I$2:$I$8217,"Belum terwakili")/10^9 -> 0.010421971 | M11: =SUMIFS(Data_Eksportir!$N$2:$N$3401,Data_Eksportir!$O$2:$O$3401,A11,Data_Eksportir!$Q$2:$Q$3401,"Wajar")/10^6 -> 0.14016826 | N11: =E11+ROW()/10^9 -> 0.03974654 | O11: =L11+ROW()/10^9 -> 0.010421982 | Q11: 6 | R11: =MATCH(LARGE($N$6:$N$104,Q11),$N$6:$N$104,0) -> 72 | S11: =TEXT(INDEX($A$6:$A$104,R11),"00")&" · "&INDEX($B$6:$B$104,R11) -> 71 · Mutiara, permata & logam mulia | T11: =INDEX($E$6:$E$104,R11) -> 10.777363 | U11: =INDEX($F$6:$F$104,R11) -> 0.045933519 | V11: =INDEX($I$6:$I$104,R11) -> 0.0006466214 | W11: =IFERROR(V11/U11,"") -> 0.014077332 | X11: =INDEX($H$6:$H$104,R11) -> 2
A12: 6 | B12: Tanaman hidup & bunga | C12: =COUNTIFS(Data_HS!$F$2:$F$8217,A12,Data_HS!$D$2:$D$8217,">0") -> 21 | D12: =SUMIFS(Data_HS!$C$2:$C$8217,Data_HS!$F$2:$F$8217,A12)/10^9 -> 0.006786545 | E12: =SUMIFS(Data_HS!$D$2:$D$8217,Data_HS!$F$2:$F$8217,A12)/10^9 -> 0.01988095 | F12: =E12/$E$105 -> 8.4733339e-05 | G12: =IFERROR(SUMIFS(Data_HS!$D$2:$D$8217,Data_HS!$F$2:$F$8217,A12,Data_HS!$C$2:$C$8217,">0")/SUMIFS(Data_HS!$C$2:$C$8217,Data_HS!$F$2:$F$8217,A12),"") -> 2.9294656 | H12: =COUNTIF(Data_Eksportir!$O$2:$O$3401,A12) -> 4 | I12: =IF(A12=0,"",H12/COUNTIF(Data_Eksportir!$O$2:$O$3401,">0")) -> 0.0012932428 | J12: =IF(OR(A12=0,F12=0),"",I12/F12) -> 15.262503 | K12: =COUNTIFS(Data_HS!$F$2:$F$8217,A12,Data_HS!$I$2:$I$8217,"Belum terwakili") -> 0 | L12: =SUMIFS(Data_HS!$D$2:$D$8217,Data_HS!$F$2:$F$8217,A12,Data_HS!$I$2:$I$8217,"Belum terwakili")/10^9 -> 0 | M12: =SUMIFS(Data_Eksportir!$N$2:$N$3401,Data_Eksportir!$O$2:$O$3401,A12,Data_Eksportir!$Q$2:$Q$3401,"Wajar")/10^6 -> 0.028312811 | N12: =E12+ROW()/10^9 -> 0.019880962 | O12: =L12+ROW()/10^9 -> 1.2e-08 | Q12: 7 | R12: =MATCH(LARGE($N$6:$N$104,Q12),$N$6:$N$104,0) -> 39 | S12: =TEXT(INDEX($A$6:$A$104,R12),"00")&" · "&INDEX($B$6:$B$104,R12) -> 38 · Produk kimia lainnya | T12: =INDEX($E$6:$E$104,R12) -> 8.6399942 | U12: =INDEX($F$6:$F$104,R12) -> 0.036823973 | V12: =INDEX($I$6:$I$104,R12) -> 0.07824119 | W12: =IFERROR(V12/U12,"") -> 2.1247352 | X12: =INDEX($H$6:$H$104,R12) -> 242
A13: 7 | B13: Sayuran & umbi | C13: =COUNTIFS(Data_HS!$F$2:$F$8217,A13,Data_HS!$D$2:$D$8217,">0") -> 83 | D13: =SUMIFS(Data_HS!$C$2:$C$8217,Data_HS!$F$2:$F$8217,A13)/10^9 -> 0.11240872 | E13: =SUMIFS(Data_HS!$D$2:$D$8217,Data_HS!$F$2:$F$8217,A13)/10^9 -> 0.098891759 | F13: =E13/$E$105 -> 0.00042148031 | G13: =IFERROR(SUMIFS(Data_HS!$D$2:$D$8217,Data_HS!$F$2:$F$8217,A13,Data_HS!$C$2:$C$8217,">0")/SUMIFS(Data_HS!$C$2:$C$8217,Data_HS!$F$2:$F$8217,A13),"") -> 0.87975169 | H13: =COUNTIF(Data_Eksportir!$O$2:$O$3401,A13) -> 127 | I13: =IF(A13=0,"",H13/COUNTIF(Data_Eksportir!$O$2:$O$3401,">0")) -> 0.041060459 | J13: =IF(OR(A13=0,F13=0),"",I13/F13) -> 97.419638 | K13: =COUNTIFS(Data_HS!$F$2:$F$8217,A13,Data_HS!$I$2:$I$8217,"Belum terwakili") -> 2 | L13: =SUMIFS(Data_HS!$D$2:$D$8217,Data_HS!$F$2:$F$8217,A13,Data_HS!$I$2:$I$8217,"Belum terwakili")/10^9 -> 0.045965723 | M13: =SUMIFS(Data_Eksportir!$N$2:$N$3401,Data_Eksportir!$O$2:$O$3401,A13,Data_Eksportir!$Q$2:$Q$3401,"Wajar")/10^6 -> 1.2088704 | N13: =E13+ROW()/10^9 -> 0.098891772 | O13: =L13+ROW()/10^9 -> 0.045965736 | Q13: 8 | R13: =MATCH(LARGE($N$6:$N$104,Q13),$N$6:$N$104,0) -> 76 | S13: =TEXT(INDEX($A$6:$A$104,R13),"00")&" · "&INDEX($B$6:$B$104,R13) -> 75 · Nikel | T13: =INDEX($E$6:$E$104,R13) -> 8.4561202 | U13: =INDEX($F$6:$F$104,R13) -> 0.036040295 | V13: =INDEX($I$6:$I$104,R13) -> 0 | W13: =IFERROR(V13/U13,"") -> 0 | X13: =INDEX($H$6:$H$104,R13) -> 0
A14: 8 | B14: Buah & kacang-kacangan | C14: =COUNTIFS(Data_HS!$F$2:$F$8217,A14,Data_HS!$D$2:$D$8217,">0") -> 76 | D14: =SUMIFS(Data_HS!$C$2:$C$8217,Data_HS!$F$2:$F$8217,A14)/10^9 -> 1.7455757 | E14: =SUMIFS(Data_HS!$D$2:$D$8217,Data_HS!$F$2:$F$8217,A14)/10^9 -> 1.3332451 | F14: =E14/$E$105 -> 0.0056823394 | G14: =IFERROR(SUMIFS(Data_HS!$D$2:$D$8217,Data_HS!$F$2:$F$8217,A14,Data_HS!$C$2:$C$8217,">0")/SUMIFS(Data_HS!$C$2:$C$8217,Data_HS!$F$2:$F$8217,A14),"") -> 0.76378531 | H14: =COUNTIF(Data_Eksportir!$O$2:$O$3401,A14) -> 252 | I14: =IF(A14=0,"",H14/COUNTIF(Data_Eksportir!$O$2:$O$3401,">0")) -> 0.081474297 | J14: =IF(OR(A14=0,F14=0),"",I14/F14) -> 14.338161 | K14: =COUNTIFS(Data_HS!$F$2:$F$8217,A14,Data_HS!$I$2:$I$8217,"Belum terwakili") -> 4 | L14: =SUMIFS(Data_HS!$D$2:$D$8217,Data_HS!$F$2:$F$8217,A14,Data_HS!$I$2:$I$8217,"Belum terwakili")/10^9 -> 0.29160744 | M14: =SUMIFS(Data_Eksportir!$N$2:$N$3401,Data_Eksportir!$O$2:$O$3401,A14,Data_Eksportir!$Q$2:$Q$3401,"Wajar")/10^6 -> 9.5562306 | N14: =E14+ROW()/10^9 -> 1.3332451 | O14: =L14+ROW()/10^9 -> 0.29160745 | Q14: 9 | R14: =MATCH(LARGE($N$6:$N$104,Q14),$N$6:$N$104,0) -> 84 | S14: =TEXT(INDEX($A$6:$A$104,R14),"00")&" · "&INDEX($B$6:$B$104,R14) -> 84 · Mesin & peralatan mekanis | T14: =INDEX($E$6:$E$104,R14) -> 7.4133267 | U14: =INDEX($F$6:$F$104,R14) -> 0.031595871 | V14: =INDEX($I$6:$I$104,R14) -> 0.010345942 | W14: =IFERROR(V14/U14,"") -> 0.32744603 | X14: =INDEX($H$6:$H$104,R14) -> 32
A15: 9 | B15: Kopi, teh & rempah | C15: =COUNTIFS(Data_HS!$F$2:$F$8217,A15,Data_HS!$D$2:$D$8217,">0") -> 62 | D15: =SUMIFS(Data_HS!$C$2:$C$8217,Data_HS!$F$2:$F$8217,A15)/10^9 -> 0.64447955 | E15: =SUMIFS(Data_HS!$D$2:$D$8217,Data_HS!$F$2:$F$8217,A15)/10^9 -> 3.1745151 | F15: =E15/$E$105 -> 0.0135299 | G15: =IFERROR(SUMIFS(Data_HS!$D$2:$D$8217,Data_HS!$F$2:$F$8217,A15,Data_HS!$C$2:$C$8217,">0")/SUMIFS(Data_HS!$C$2:$C$8217,Data_HS!$F$2:$F$8217,A15),"") -> 4.9257032 | H15: =COUNTIF(Data_Eksportir!$O$2:$O$3401,A15) -> 827 | I15: =IF(A15=0,"",H15/COUNTIF(Data_Eksportir!$O$2:$O$3401,">0")) -> 0.26737795 | J15: =IF(OR(A15=0,F15=0),"",I15/F15) -> 19.762005 | K15: =COUNTIFS(Data_HS!$F$2:$F$8217,A15,Data_HS!$I$2:$I$8217,"Belum terwakili") -> 4 | L15: =SUMIFS(Data_HS!$D$2:$D$8217,Data_HS!$F$2:$F$8217,A15,Data_HS!$I$2:$I$8217,"Belum terwakili")/10^9 -> 0.1586538 | M15: =SUMIFS(Data_Eksportir!$N$2:$N$3401,Data_Eksportir!$O$2:$O$3401,A15,Data_Eksportir!$Q$2:$Q$3401,"Wajar")/10^6 -> 75.838899 | N15: =E15+ROW()/10^9 -> 3.1745151 | O15: =L15+ROW()/10^9 -> 0.15865382 | Q15: 10 | R15: =MATCH(LARGE($N$6:$N$104,Q15),$N$6:$N$104,0) -> 65 | S15: =TEXT(INDEX($A$6:$A$104,R15),"00")&" · "&INDEX($B$6:$B$104,R15) -> 64 · Alas kaki | T15: =INDEX($E$6:$E$104,R15) -> 5.1029468 | U15: =INDEX($F$6:$F$104,R15) -> 0.021748947 | V15: =INDEX($I$6:$I$104,R15) -> 0.0045263498 | W15: =IFERROR(V15/U15,"") -> 0.20811812 | X15: =INDEX($H$6:$H$104,R15) -> 14
A16: 10 | B16: Serealia | C16: =COUNTIFS(Data_HS!$F$2:$F$8217,A16,Data_HS!$D$2:$D$8217,">0") -> 19 | D16: =SUMIFS(Data_HS!$C$2:$C$8217,Data_HS!$F$2:$F$8217,A16)/10^9 -> 0.007789274 | E16: =SUMIFS(Data_HS!$D$2:$D$8217,Data_HS!$F$2:$F$8217,A16)/10^9 -> 0.005560159 | F16: =E16/$E$105 -> 2.3697602e-05 | G16: =IFERROR(SUMIFS(Data_HS!$D$2:$D$8217,Data_HS!$F$2:$F$8217,A16,Data_HS!$C$2:$C$8217,">0")/SUMIFS(Data_HS!$C$2:$C$8217,Data_HS!$F$2:$F$8217,A16),"") -> 0.71382249 | H16: =COUNTIF(Data_Eksportir!$O$2:$O$3401,A16) -> 77 | I16: =IF(A16=0,"",H16/COUNTIF(Data_Eksportir!$O$2:$O$3401,">0")) -> 0.024894924 | J16: =IF(OR(A16=0,F16=0),"",I16/F16) -> 1050.525 | K16: =COUNTIFS(Data_HS!$F$2:$F$8217,A16,Data_HS!$I$2:$I$8217,"Belum terwakili") -> 0 | L16: =SUMIFS(Data_HS!$D$2:$D$8217,Data_HS!$F$2:$F$8217,A16,Data_HS!$I$2:$I$8217,"Belum terwakili")/10^9 -> 0 | M16: =SUMIFS(Data_Eksportir!$N$2:$N$3401,Data_Eksportir!$O$2:$O$3401,A16,Data_Eksportir!$Q$2:$Q$3401,"Wajar")/10^6 -> 0.12542886 | N16: =E16+ROW()/10^9 -> 0.005560175 | O16: =L16+ROW()/10^9 -> 1.6e-08
A17: 11 | B17: Produk penggilingan & pati | C17: =COUNTIFS(Data_HS!$F$2:$F$8217,A17,Data_HS!$D$2:$D$8217,">0") -> 33 | D17: =SUMIFS(Data_HS!$C$2:$C$8217,Data_HS!$F$2:$F$8217,A17)/10^9 -> 0.17628103 | E17: =SUMIFS(Data_HS!$D$2:$D$8217,Data_HS!$F$2:$F$8217,A17)/10^9 -> 0.089289736 | F17: =E17/$E$105 -> 0.00038055613 | G17: =IFERROR(SUMIFS(Data_HS!$D$2:$D$8217,Data_HS!$F$2:$F$8217,A17,Data_HS!$C$2:$C$8217,">0")/SUMIFS(Data_HS!$C$2:$C$8217,Data_HS!$F$2:$F$8217,A17),"") -> 0.50651926 | H17: =COUNTIF(Data_Eksportir!$O$2:$O$3401,A17) -> 40 | I17: =IF(A17=0,"",H17/COUNTIF(Data_Eksportir!$O$2:$O$3401,">0")) -> 0.012932428 | J17: =IF(OR(A17=0,F17=0),"",I17/F17) -> 33.982971 | K17: =COUNTIFS(Data_HS!$F$2:$F$8217,A17,Data_HS!$I$2:$I$8217,"Belum terwakili") -> 2 | L17: =SUMIFS(Data_HS!$D$2:$D$8217,Data_HS!$F$2:$F$8217,A17,Data_HS!$I$2:$I$8217,"Belum terwakili")/10^9 -> 0.044368613 | M17: =SUMIFS(Data_Eksportir!$N$2:$N$3401,Data_Eksportir!$O$2:$O$3401,A17,Data_Eksportir!$Q$2:$Q$3401,"Wajar")/10^6 -> 0.80791612 | N17: =E17+ROW()/10^9 -> 0.089289753 | O17: =L17+ROW()/10^9 -> 0.04436863 | Q17: Top 10 bab menurut nilai HS yang belum terwakili di direktori
A18: 12 | B18: Biji & buah berminyak | C18: =COUNTIFS(Data_HS!$F$2:$F$8217,A18,Data_HS!$D$2:$D$8217,">0") -> 57 | D18: =SUMIFS(Data_HS!$C$2:$C$8217,Data_HS!$F$2:$F$8217,A18)/10^9 -> 0.30017293 | E18: =SUMIFS(Data_HS!$D$2:$D$8217,Data_HS!$F$2:$F$8217,A18)/10^9 -> 0.49876592 | F18: =E18/$E$105 -> 0.0021257587 | G18: =IFERROR(SUMIFS(Data_HS!$D$2:$D$8217,Data_HS!$F$2:$F$8217,A18,Data_HS!$C$2:$C$8217,">0")/SUMIFS(Data_HS!$C$2:$C$8217,Data_HS!$F$2:$F$8217,A18),"") -> 1.6615953 | H18: =COUNTIF(Data_Eksportir!$O$2:$O$3401,A18) -> 88 | I18: =IF(A18=0,"",H18/COUNTIF(Data_Eksportir!$O$2:$O$3401,">0")) -> 0.028451342 | J18: =IF(OR(A18=0,F18=0),"",I18/F18) -> 13.384088 | K18: =COUNTIFS(Data_HS!$F$2:$F$8217,A18,Data_HS!$I$2:$I$8217,"Belum terwakili") -> 3 | L18: =SUMIFS(Data_HS!$D$2:$D$8217,Data_HS!$F$2:$F$8217,A18,Data_HS!$I$2:$I$8217,"Belum terwakili")/10^9 -> 0.25870226 | M18: =SUMIFS(Data_Eksportir!$N$2:$N$3401,Data_Eksportir!$O$2:$O$3401,A18,Data_Eksportir!$Q$2:$Q$3401,"Wajar")/10^6 -> 9.2326424 | N18: =E18+ROW()/10^9 -> 0.49876594 | O18: =L18+ROW()/10^9 -> 0.25870228 | Q18: Peringkat | R18: Baris (helper) | S18: Bab | T18: Nilai belum terwakili (USD miliar) | U18: Jml HS belum terwakili
A19: 13 | B19: Getah, gom & resin nabati | C19: =COUNTIFS(Data_HS!$F$2:$F$8217,A19,Data_HS!$D$2:$D$8217,">0") -> 16 | D19: =SUMIFS(Data_HS!$C$2:$C$8217,Data_HS!$F$2:$F$8217,A19)/10^9 -> 0.060181227 | E19: =SUMIFS(Data_HS!$D$2:$D$8217,Data_HS!$F$2:$F$8217,A19)/10^9 -> 0.1790012 | F19: =E19/$E$105 -> 0.00076290967 | G19: =IFERROR(SUMIFS(Data_HS!$D$2:$D$8217,Data_HS!$F$2:$F$8217,A19,Data_HS!$C$2:$C$8217,">0")/SUMIFS(Data_HS!$C$2:$C$8217,Data_HS!$F$2:$F$8217,A19),"") -> 2.9743673 | H19: =COUNTIF(Data_Eksportir!$O$2:$O$3401,A19) -> 7 | I19: =IF(A19=0,"",H19/COUNTIF(Data_Eksportir!$O$2:$O$3401,">0")) -> 0.0022631749 | J19: =IF(OR(A19=0,F19=0),"",I19/F19) -> 2.9665044 | K19: =COUNTIFS(Data_HS!$F$2:$F$8217,A19,Data_HS!$I$2:$I$8217,"Belum terwakili") -> 2 | L19: =SUMIFS(Data_HS!$D$2:$D$8217,Data_HS!$F$2:$F$8217,A19,Data_HS!$I$2:$I$8217,"Belum terwakili")/10^9 -> 0.14629173 | M19: =SUMIFS(Data_Eksportir!$N$2:$N$3401,Data_Eksportir!$O$2:$O$3401,A19,Data_Eksportir!$Q$2:$Q$3401,"Wajar")/10^6 -> 0.024429917 | N19: =E19+ROW()/10^9 -> 0.17900121 | O19: =L19+ROW()/10^9 -> 0.14629175 | Q19: 1 | R19: =MATCH(LARGE($O$6:$O$104,Q19),$O$6:$O$104,0) -> 73 | S19: =TEXT(INDEX($A$6:$A$104,R19),"00")&" · "&INDEX($B$6:$B$104,R19) -> 72 · Besi & baja | T19: =INDEX($L$6:$L$104,R19) -> 24.445481 | U19: =INDEX($K$6:$K$104,R19) -> 31
A20: 14 | B20: Bahan anyaman nabati | C20: =COUNTIFS(Data_HS!$F$2:$F$8217,A20,Data_HS!$D$2:$D$8217,">0") -> 8 | D20: =SUMIFS(Data_HS!$C$2:$C$8217,Data_HS!$F$2:$F$8217,A20)/10^9 -> 5.4643838 | E20: =SUMIFS(Data_HS!$D$2:$D$8217,Data_HS!$F$2:$F$8217,A20)/10^9 -> 0.57399589 | F20: =E20/$E$105 -> 0.0024463916 | G20: =IFERROR(SUMIFS(Data_HS!$D$2:$D$8217,Data_HS!$F$2:$F$8217,A20,Data_HS!$C$2:$C$8217,">0")/SUMIFS(Data_HS!$C$2:$C$8217,Data_HS!$F$2:$F$8217,A20),"") -> 0.10504311 | H20: =COUNTIF(Data_Eksportir!$O$2:$O$3401,A20) -> 54 | I20: =IF(A20=0,"",H20/COUNTIF(Data_Eksportir!$O$2:$O$3401,">0")) -> 0.017458778 | J20: =IF(OR(A20=0,F20=0),"",I20/F20) -> 7.1365427 | K20: =COUNTIFS(Data_HS!$F$2:$F$8217,A20,Data_HS!$I$2:$I$8217,"Belum terwakili") -> 0 | L20: =SUMIFS(Data_HS!$D$2:$D$8217,Data_HS!$F$2:$F$8217,A20,Data_HS!$I$2:$I$8217,"Belum terwakili")/10^9 -> 0 | M20: =SUMIFS(Data_Eksportir!$N$2:$N$3401,Data_Eksportir!$O$2:$O$3401,A20,Data_Eksportir!$Q$2:$Q$3401,"Wajar")/10^6 -> 27.890816 | N20: =E20+ROW()/10^9 -> 0.57399591 | O20: =L20+ROW()/10^9 -> 2e-08 | Q20: 2 | R20: =MATCH(LARGE($O$6:$O$104,Q20),$O$6:$O$104,0) -> 16 | S20: =TEXT(INDEX($A$6:$A$104,R20),"00")&" · "&INDEX($B$6:$B$104,R20) -> 15 · Lemak & minyak nabati/hewani | T20: =INDEX($L$6:$L$104,R20) -> 23.230673 | U20: =INDEX($K$6:$K$104,R20) -> 28
A21: 15 | B21: Lemak & minyak nabati/hewani | C21: =COUNTIFS(Data_HS!$F$2:$F$8217,A21,Data_HS!$D$2:$D$8217,">0") -> 111 | D21: =SUMIFS(Data_HS!$C$2:$C$8217,Data_HS!$F$2:$F$8217,A21)/10^9 -> 27.846508 | E21: =SUMIFS(Data_HS!$D$2:$D$8217,Data_HS!$F$2:$F$8217,A21)/10^9 -> 30.574903 | F21: =E21/$E$105 -> 0.13031136 | G21: =IFERROR(SUMIFS(Data_HS!$D$2:$D$8217,Data_HS!$F$2:$F$8217,A21,Data_HS!$C$2:$C$8217,">0")/SUMIFS(Data_HS!$C$2:$C$8217,Data_HS!$F$2:$F$8217,A21),"") -> 1.0979798 | H21: =COUNTIF(Data_Eksportir!$O$2:$O$3401,A21) -> 130 | I21: =IF(A21=0,"",H21/COUNTIF(Data_Eksportir!$O$2:$O$3401,">0")) -> 0.042030391 | J21: =IF(OR(A21=0,F21=0),"",I21/F21) -> 0.3225382 | K21: =COUNTIFS(Data_HS!$F$2:$F$8217,A21,Data_HS!$I$2:$I$8217,"Belum terwakili") -> 28 | L21: =SUMIFS(Data_HS!$D$2:$D$8217,Data_HS!$F$2:$F$8217,A21,Data_HS!$I$2:$I$8217,"Belum terwakili")/10^9 -> 23.230673 | M21: =SUMIFS(Data_Eksportir!$N$2:$N$3401,Data_Eksportir!$O$2:$O$3401,A21,Data_Eksportir!$Q$2:$Q$3401,"Wajar")/10^6 -> 195.82758 | N21: =E21+ROW()/10^9 -> 30.574903 | O21: =L21+ROW()/10^9 -> 23.230673 | Q21: 3 | R21: =MATCH(LARGE($O$6:$O$104,Q21),$O$6:$O$104,0) -> 28 | S21: =TEXT(INDEX($A$6:$A$104,R21),"00")&" · "&INDEX($B$6:$B$104,R21) -> 27 · Batubara, migas & bahan bakar | T21: =INDEX($L$6:$L$104,R21) -> 21.471178 | U21: =INDEX($K$6:$K$104,R21) -> 22
A22: 16 | B22: Olahan daging & ikan | C22: =COUNTIFS(Data_HS!$F$2:$F$8217,A22,Data_HS!$D$2:$D$8217,">0") -> 63 | D22: =SUMIFS(Data_HS!$C$2:$C$8217,Data_HS!$F$2:$F$8217,A22)/10^9 -> 0.19626269 | E22: =SUMIFS(Data_HS!$D$2:$D$8217,Data_HS!$F$2:$F$8217,A22)/10^9 -> 1.3531696 | F22: =E22/$E$105 -> 0.0057672585 | G22: =IFERROR(SUMIFS(Data_HS!$D$2:$D$8217,Data_HS!$F$2:$F$8217,A22,Data_HS!$C$2:$C$8217,">0")/SUMIFS(Data_HS!$C$2:$C$8217,Data_HS!$F$2:$F$8217,A22),"") -> 6.8946859 | H22: =COUNTIF(Data_Eksportir!$O$2:$O$3401,A22) -> 9 | I22: =IF(A22=0,"",H22/COUNTIF(Data_Eksportir!$O$2:$O$3401,">0")) -> 0.0029097963 | J22: =IF(OR(A22=0,F22=0),"",I22/F22) -> 0.50453717 | K22: =COUNTIFS(Data_HS!$F$2:$F$8217,A22,Data_HS!$I$2:$I$8217,"Belum terwakili") -> 14 | L22: =SUMIFS(Data_HS!$D$2:$D$8217,Data_HS!$F$2:$F$8217,A22,Data_HS!$I$2:$I$8217,"Belum terwakili")/10^9 -> 1.2878734 | M22: =SUMIFS(Data_Eksportir!$N$2:$N$3401,Data_Eksportir!$O$2:$O$3401,A22,Data_Eksportir!$Q$2:$Q$3401,"Wajar")/10^6 -> 0.72277498 | N22: =E22+ROW()/10^9 -> 1.3531696 | O22: =L22+ROW()/10^9 -> 1.2878734 | Q22: 4 | R22: =MATCH(LARGE($O$6:$O$104,Q22),$O$6:$O$104,0) -> 85 | S22: =TEXT(INDEX($A$6:$A$104,R22),"00")&" · "&INDEX($B$6:$B$104,R22) -> 85 · Mesin listrik & elektronik | T22: =INDEX($L$6:$L$104,R22) -> 15.585381 | U22: =INDEX($K$6:$K$104,R22) -> 141
A23: 17 | B23: Gula & kembang gula | C23: =COUNTIFS(Data_HS!$F$2:$F$8217,A23,Data_HS!$D$2:$D$8217,">0") -> 32 | D23: =SUMIFS(Data_HS!$C$2:$C$8217,Data_HS!$F$2:$F$8217,A23)/10^9 -> 0.90922792 | E23: =SUMIFS(Data_HS!$D$2:$D$8217,Data_HS!$F$2:$F$8217,A23)/10^9 -> 0.42006576 | F23: =E23/$E$105 -> 0.0017903357 | G23: =IFERROR(SUMIFS(Data_HS!$D$2:$D$8217,Data_HS!$F$2:$F$8217,A23,Data_HS!$C$2:$C$8217,">0")/SUMIFS(Data_HS!$C$2:$C$8217,Data_HS!$F$2:$F$8217,A23),"") -> 0.4620027 | H23: =COUNTIF(Data_Eksportir!$O$2:$O$3401,A23) -> 81 | I23: =IF(A23=0,"",H23/COUNTIF(Data_Eksportir!$O$2:$O$3401,">0")) -> 0.026188167 | J23: =IF(OR(A23=0,F23=0),"",I23/F23) -> 14.627518 | K23: =COUNTIFS(Data_HS!$F$2:$F$8217,A23,Data_HS!$I$2:$I$8217,"Belum terwakili") -> 5 | L23: =SUMIFS(Data_HS!$D$2:$D$8217,Data_HS!$F$2:$F$8217,A23,Data_HS!$I$2:$I$8217,"Belum terwakili")/10^9 -> 0.36451348 | M23: =SUMIFS(Data_Eksportir!$N$2:$N$3401,Data_Eksportir!$O$2:$O$3401,A23,Data_Eksportir!$Q$2:$Q$3401,"Wajar")/10^6 -> 4.0470731 | N23: =E23+ROW()/10^9 -> 0.42006578 | O23: =L23+ROW()/10^9 -> 0.3645135 | Q23: 5 | R23: =MATCH(LARGE($O$6:$O$104,Q23),$O$6:$O$104,0) -> 72 | S23: =TEXT(INDEX($A$6:$A$104,R23),"00")&" · "&INDEX($B$6:$B$104,R23) -> 71 · Mutiara, permata & logam mulia | T23: =INDEX($L$6:$L$104,R23) -> 10.678077 | U23: =INDEX($K$6:$K$104,R23) -> 11
A24: 18 | B24: Kakao & olahannya | C24: =COUNTIFS(Data_HS!$F$2:$F$8217,A24,Data_HS!$D$2:$D$8217,">0") -> 16 | D24: =SUMIFS(Data_HS!$C$2:$C$8217,Data_HS!$F$2:$F$8217,A24)/10^9 -> 0.31666107 | E24: =SUMIFS(Data_HS!$D$2:$D$8217,Data_HS!$F$2:$F$8217,A24)/10^9 -> 3.3654286 | F24: =E24/$E$105 -> 0.01434358 | G24: =IFERROR(SUMIFS(Data_HS!$D$2:$D$8217,Data_HS!$F$2:$F$8217,A24,Data_HS!$C$2:$C$8217,">0")/SUMIFS(Data_HS!$C$2:$C$8217,Data_HS!$F$2:$F$8217,A24),"") -> 10.627857 | H24: =COUNTIF(Data_Eksportir!$O$2:$O$3401,A24) -> 93 | I24: =IF(A24=0,"",H24/COUNTIF(Data_Eksportir!$O$2:$O$3401,">0")) -> 0.030067895 | J24: =IF(OR(A24=0,F24=0),"",I24/F24) -> 2.0962615 | K24: =COUNTIFS(Data_HS!$F$2:$F$8217,A24,Data_HS!$I$2:$I$8217,"Belum terwakili") -> 3 | L24: =SUMIFS(Data_HS!$D$2:$D$8217,Data_HS!$F$2:$F$8217,A24,Data_HS!$I$2:$I$8217,"Belum terwakili")/10^9 -> 0.30437157 | M24: =SUMIFS(Data_Eksportir!$N$2:$N$3401,Data_Eksportir!$O$2:$O$3401,A24,Data_Eksportir!$Q$2:$Q$3401,"Wajar")/10^6 -> 170.56714 | N24: =E24+ROW()/10^9 -> 3.3654286 | O24: =L24+ROW()/10^9 -> 0.3043716 | Q24: 6 | R24: =MATCH(LARGE($O$6:$O$104,Q24),$O$6:$O$104,0) -> 87 | S24: =TEXT(INDEX($A$6:$A$104,R24),"00")&" · "&INDEX($B$6:$B$104,R24) -> 87 · Kendaraan bermotor | T24: =INDEX($L$6:$L$104,R24) -> 10.599114 | U24: =INDEX($K$6:$K$104,R24) -> 72
A25: 19 | B25: Olahan tepung & roti | C25: =COUNTIFS(Data_HS!$F$2:$F$8217,A25,Data_HS!$D$2:$D$8217,">0") -> 57 | D25: =SUMIFS(Data_HS!$C$2:$C$8217,Data_HS!$F$2:$F$8217,A25)/10^9 -> 0.6605908 | E25: =SUMIFS(Data_HS!$D$2:$D$8217,Data_HS!$F$2:$F$8217,A25)/10^9 -> 1.5250503 | F25: =E25/$E$105 -> 0.0064998203 | G25: =IFERROR(SUMIFS(Data_HS!$D$2:$D$8217,Data_HS!$F$2:$F$8217,A25,Data_HS!$C$2:$C$8217,">0")/SUMIFS(Data_HS!$C$2:$C$8217,Data_HS!$F$2:$F$8217,A25),"") -> 2.3086155 | H25: =COUNTIF(Data_Eksportir!$O$2:$O$3401,A25) -> 19 | I25: =IF(A25=0,"",H25/COUNTIF(Data_Eksportir!$O$2:$O$3401,">0")) -> 0.0061429033 | J25: =IF(OR(A25=0,F25=0),"",I25/F25) -> 0.94508818 | K25: =COUNTIFS(Data_HS!$F$2:$F$8217,A25,Data_HS!$I$2:$I$8217,"Belum terwakili") -> 12 | L25: =SUMIFS(Data_HS!$D$2:$D$8217,Data_HS!$F$2:$F$8217,A25,Data_HS!$I$2:$I$8217,"Belum terwakili")/10^9 -> 0.76684902 | M25: =SUMIFS(Data_Eksportir!$N$2:$N$3401,Data_Eksportir!$O$2:$O$3401,A25,Data_Eksportir!$Q$2:$Q$3401,"Wajar")/10^6 -> 0.94979613 | N25: =E25+ROW()/10^9 -> 1.5250503 | O25: =L25+ROW()/10^9 -> 0.76684904 | Q25: 7 | R25: =MATCH(LARGE($O$6:$O$104,Q25),$O$6:$O$104,0) -> 76 | S25: =TEXT(INDEX($A$6:$A$104,R25),"00")&" · "&INDEX($B$6:$B$104,R25) -> 75 · Nikel | T25: =INDEX($L$6:$L$104,R25) -> 8.4452439 | U25: =INDEX($K$6:$K$104,R25) -> 3
A26: 20 | B26: Olahan sayur & buah | C26: =COUNTIFS(Data_HS!$F$2:$F$8217,A26,Data_HS!$D$2:$D$8217,">0") -> 69 | D26: =SUMIFS(Data_HS!$C$2:$C$8217,Data_HS!$F$2:$F$8217,A26)/10^9 -> 0.26972792 | E26: =SUMIFS(Data_HS!$D$2:$D$8217,Data_HS!$F$2:$F$8217,A26)/10^9 -> 0.46093583 | F26: =E26/$E$105 -> 0.0019645254 | G26: =IFERROR(SUMIFS(Data_HS!$D$2:$D$8217,Data_HS!$F$2:$F$8217,A26,Data_HS!$C$2:$C$8217,">0")/SUMIFS(Data_HS!$C$2:$C$8217,Data_HS!$F$2:$F$8217,A26),"") -> 1.7088918 | H26: =COUNTIF(Data_Eksportir!$O$2:$O$3401,A26) -> 60 | I26: =IF(A26=0,"",H26/COUNTIF(Data_Eksportir!$O$2:$O$3401,">0")) -> 0.019398642 | J26: =IF(OR(A26=0,F26=0),"",I26/F26) -> 9.8744673 | K26: =COUNTIFS(Data_HS!$F$2:$F$8217,A26,Data_HS!$I$2:$I$8217,"Belum terwakili") -> 3 | L26: =SUMIFS(Data_HS!$D$2:$D$8217,Data_HS!$F$2:$F$8217,A26,Data_HS!$I$2:$I$8217,"Belum terwakili")/10^9 -> 0.31454055 | M26: =SUMIFS(Data_Eksportir!$N$2:$N$3401,Data_Eksportir!$O$2:$O$3401,A26,Data_Eksportir!$Q$2:$Q$3401,"Wajar")/10^6 -> 1.0353413 | N26: =E26+ROW()/10^9 -> 0.46093585 | O26: =L26+ROW()/10^9 -> 0.31454057 | Q26: 8 | R26: =MATCH(LARGE($O$6:$O$104,Q26),$O$6:$O$104,0) -> 84 | S26: =TEXT(INDEX($A$6:$A$104,R26),"00")&" · "&INDEX($B$6:$B$104,R26) -> 84 · Mesin & peralatan mekanis | T26: =INDEX($L$6:$L$104,R26) -> 6.6888486 | U26: =INDEX($K$6:$K$104,R26) -> 96
A27: 21 | B27: Olahan makanan lainnya | C27: =COUNTIFS(Data_HS!$F$2:$F$8217,A27,Data_HS!$D$2:$D$8217,">0") -> 56 | D27: =SUMIFS(Data_HS!$C$2:$C$8217,Data_HS!$F$2:$F$8217,A27)/10^9 -> 0.67347292 | E27: =SUMIFS(Data_HS!$D$2:$D$8217,Data_HS!$F$2:$F$8217,A27)/10^9 -> 1.7877899 | F27: =E27/$E$105 -> 0.0076196264 | G27: =IFERROR(SUMIFS(Data_HS!$D$2:$D$8217,Data_HS!$F$2:$F$8217,A27,Data_HS!$C$2:$C$8217,">0")/SUMIFS(Data_HS!$C$2:$C$8217,Data_HS!$F$2:$F$8217,A27),"") -> 2.6545832 | H27: =COUNTIF(Data_Eksportir!$O$2:$O$3401,A27) -> 51 | I27: =IF(A27=0,"",H27/COUNTIF(Data_Eksportir!$O$2:$O$3401,">0")) -> 0.016488846 | J27: =IF(OR(A27=0,F27=0),"",I27/F27) -> 2.1639966 | K27: =COUNTIFS(Data_HS!$F$2:$F$8217,A27,Data_HS!$I$2:$I$8217,"Belum terwakili") -> 14 | L27: =SUMIFS(Data_HS!$D$2:$D$8217,Data_HS!$F$2:$F$8217,A27,Data_HS!$I$2:$I$8217,"Belum terwakili")/10^9 -> 0.80312026 | M27: =SUMIFS(Data_Eksportir!$N$2:$N$3401,Data_Eksportir!$O$2:$O$3401,A27,Data_Eksportir!$Q$2:$Q$3401,"Wajar")/10^6 -> 1.0149949 | N27: =E27+ROW()/10^9 -> 1.78779 | O27: =L27+ROW()/10^9 -> 0.80312029 | Q27: 9 | R27: =MATCH(LARGE($O$6:$O$104,Q27),$O$6:$O$104,0) -> 39 | S27: =TEXT(INDEX($A$6:$A$104,R27),"00")&" · "&INDEX($B$6:$B$104,R27) -> 38 · Produk kimia lainnya | T27: =INDEX($L$6:$L$104,R27) -> 6.5637392 | U27: =INDEX($K$6:$K$104,R27) -> 26
A28: 22 | B28: Minuman & cuka | C28: =COUNTIFS(Data_HS!$F$2:$F$8217,A28,Data_HS!$D$2:$D$8217,">0") -> 47 | D28: =SUMIFS(Data_HS!$C$2:$C$8217,Data_HS!$F$2:$F$8217,A28)/10^9 -> 0.44864151 | E28: =SUMIFS(Data_HS!$D$2:$D$8217,Data_HS!$F$2:$F$8217,A28)/10^9 -> 0.28287226 | F28: =E28/$E$105 -> 0.001205612 | G28: =IFERROR(SUMIFS(Data_HS!$D$2:$D$8217,Data_HS!$F$2:$F$8217,A28,Data_HS!$C$2:$C$8217,">0")/SUMIFS(Data_HS!$C$2:$C$8217,Data_HS!$F$2:$F$8217,A28),"") -> 0.63050812 | H28: =COUNTIF(Data_Eksportir!$O$2:$O$3401,A28) -> 8 | I28: =IF(A28=0,"",H28/COUNTIF(Data_Eksportir!$O$2:$O$3401,">0")) -> 0.0025864856 | J28: =IF(OR(A28=0,F28=0),"",I28/F28) -> 2.1453716 | K28: =COUNTIFS(Data_HS!$F$2:$F$8217,A28,Data_HS!$I$2:$I$8217,"Belum terwakili") -> 6 | L28: =SUMIFS(Data_HS!$D$2:$D$8217,Data_HS!$F$2:$F$8217,A28,Data_HS!$I$2:$I$8217,"Belum terwakili")/10^9 -> 0.24882477 | M28: =SUMIFS(Data_Eksportir!$N$2:$N$3401,Data_Eksportir!$O$2:$O$3401,A28,Data_Eksportir!$Q$2:$Q$3401,"Wajar")/10^6 -> 0 | N28: =E28+ROW()/10^9 -> 0.28287229 | O28: =L28+ROW()/10^9 -> 0.2488248 | Q28: 10 | R28: =MATCH(LARGE($O$6:$O$104,Q28),$O$6:$O$104,0) -> 65 | S28: =TEXT(INDEX($A$6:$A$104,R28),"00")&" · "&INDEX($B$6:$B$104,R28) -> 64 · Alas kaki | T28: =INDEX($L$6:$L$104,R28) -> 5.0616357 | U28: =INDEX($K$6:$K$104,R28) -> 16
A29: 23 | B29: Sisa industri & pakan ternak | C29: =COUNTIFS(Data_HS!$F$2:$F$8217,A29,Data_HS!$D$2:$D$8217,">0") -> 32 | D29: =SUMIFS(Data_HS!$C$2:$C$8217,Data_HS!$F$2:$F$8217,A29)/10^9 -> 5.7881414 | E29: =SUMIFS(Data_HS!$D$2:$D$8217,Data_HS!$F$2:$F$8217,A29)/10^9 -> 0.91550182 | F29: =E29/$E$105 -> 0.0039019024 | G29: =IFERROR(SUMIFS(Data_HS!$D$2:$D$8217,Data_HS!$F$2:$F$8217,A29,Data_HS!$C$2:$C$8217,">0")/SUMIFS(Data_HS!$C$2:$C$8217,Data_HS!$F$2:$F$8217,A29),"") -> 0.15816853 | H29: =COUNTIF(Data_Eksportir!$O$2:$O$3401,A29) -> 54 | I29: =IF(A29=0,"",H29/COUNTIF(Data_Eksportir!$O$2:$O$3401,">0")) -> 0.017458778 | J29: =IF(OR(A29=0,F29=0),"",I29/F29) -> 4.4744271 | K29: =COUNTIFS(Data_HS!$F$2:$F$8217,A29,Data_HS!$I$2:$I$8217,"Belum terwakili") -> 8 | L29: =SUMIFS(Data_HS!$D$2:$D$8217,Data_HS!$F$2:$F$8217,A29,Data_HS!$I$2:$I$8217,"Belum terwakili")/10^9 -> 0.57117411 | M29: =SUMIFS(Data_Eksportir!$N$2:$N$3401,Data_Eksportir!$O$2:$O$3401,A29,Data_Eksportir!$Q$2:$Q$3401,"Wajar")/10^6 -> 3.3034961 | N29: =E29+ROW()/10^9 -> 0.91550185 | O29: =L29+ROW()/10^9 -> 0.57117414
A30: 24 | B30: Tembakau & rokok | C30: =COUNTIFS(Data_HS!$F$2:$F$8217,A30,Data_HS!$D$2:$D$8217,">0") -> 36 | D30: =SUMIFS(Data_HS!$C$2:$C$8217,Data_HS!$F$2:$F$8217,A30)/10^9 -> 0.16223312 | E30: =SUMIFS(Data_HS!$D$2:$D$8217,Data_HS!$F$2:$F$8217,A30)/10^9 -> 2.1071463 | F30: =E30/$E$105 -> 0.0089807348 | G30: =IFERROR(SUMIFS(Data_HS!$D$2:$D$8217,Data_HS!$F$2:$F$8217,A30,Data_HS!$C$2:$C$8217,">0")/SUMIFS(Data_HS!$C$2:$C$8217,Data_HS!$F$2:$F$8217,A30),"") -> 12.988385 | H30: =COUNTIF(Data_Eksportir!$O$2:$O$3401,A30) -> 45 | I30: =IF(A30=0,"",H30/COUNTIF(Data_Eksportir!$O$2:$O$3401,">0")) -> 0.014548982 | J30: =IF(OR(A30=0,F30=0),"",I30/F30) -> 1.6200213 | K30: =COUNTIFS(Data_HS!$F$2:$F$8217,A30,Data_HS!$I$2:$I$8217,"Belum terwakili") -> 11 | L30: =SUMIFS(Data_HS!$D$2:$D$8217,Data_HS!$F$2:$F$8217,A30,Data_HS!$I$2:$I$8217,"Belum terwakili")/10^9 -> 1.5833145 | M30: =SUMIFS(Data_Eksportir!$N$2:$N$3401,Data_Eksportir!$O$2:$O$3401,A30,Data_Eksportir!$Q$2:$Q$3401,"Wajar")/10^6 -> 36.706014 | N30: =E30+ROW()/10^9 -> 2.1071463 | O30: =L30+ROW()/10^9 -> 1.5833145
A31: 25 | B31: Garam, belerang, semen & batu | C31: =COUNTIFS(Data_HS!$F$2:$F$8217,A31,Data_HS!$D$2:$D$8217,">0") -> 50 | D31: =SUMIFS(Data_HS!$C$2:$C$8217,Data_HS!$F$2:$F$8217,A31)/10^9 -> 24.609453 | E31: =SUMIFS(Data_HS!$D$2:$D$8217,Data_HS!$F$2:$F$8217,A31)/10^9 -> 0.55274645 | F31: =E31/$E$105 -> 0.0023558257 | G31: =IFERROR(SUMIFS(Data_HS!$D$2:$D$8217,Data_HS!$F$2:$F$8217,A31,Data_HS!$C$2:$C$8217,">0")/SUMIFS(Data_HS!$C$2:$C$8217,Data_HS!$F$2:$F$8217,A31),"") -> 0.022460737 | H31: =COUNTIF(Data_Eksportir!$O$2:$O$3401,A31) -> 22 | I31: =IF(A31=0,"",H31/COUNTIF(Data_Eksportir!$O$2:$O$3401,">0")) -> 0.0071128354 | J31: =IF(OR(A31=0,F31=0),"",I31/F31) -> 3.0192537 | K31: =COUNTIFS(Data_HS!$F$2:$F$8217,A31,Data_HS!$I$2:$I$8217,"Belum terwakili") -> 5 | L31: =SUMIFS(Data_HS!$D$2:$D$8217,Data_HS!$F$2:$F$8217,A31,Data_HS!$I$2:$I$8217,"Belum terwakili")/10^9 -> 0.44967179 | M31: =SUMIFS(Data_Eksportir!$N$2:$N$3401,Data_Eksportir!$O$2:$O$3401,A31,Data_Eksportir!$Q$2:$Q$3401,"Wajar")/10^6 -> 0.041372254 | N31: =E31+ROW()/10^9 -> 0.55274648 | O31: =L31+ROW()/10^9 -> 0.44967183
A32: 26 | B32: Bijih, terak & abu logam | C32: =COUNTIFS(Data_HS!$F$2:$F$8217,A32,Data_HS!$D$2:$D$8217,">0") -> 15 | D32: =SUMIFS(Data_HS!$C$2:$C$8217,Data_HS!$F$2:$F$8217,A32)/10^9 -> 2.8581045 | E32: =SUMIFS(Data_HS!$D$2:$D$8217,Data_HS!$F$2:$F$8217,A32)/10^9 -> 4.6904165 | F32: =E32/$E$105 -> 0.019990727 | G32: =IFERROR(SUMIFS(Data_HS!$D$2:$D$8217,Data_HS!$F$2:$F$8217,A32,Data_HS!$C$2:$C$8217,">0")/SUMIFS(Data_HS!$C$2:$C$8217,Data_HS!$F$2:$F$8217,A32),"") -> 1.6410934 | H32: =COUNTIF(Data_Eksportir!$O$2:$O$3401,A32) -> 8 | I32: =IF(A32=0,"",H32/COUNTIF(Data_Eksportir!$O$2:$O$3401,">0")) -> 0.0025864856 | J32: =IF(OR(A32=0,F32=0),"",I32/F32) -> 0.12938427 | K32: =COUNTIFS(Data_HS!$F$2:$F$8217,A32,Data_HS!$I$2:$I$8217,"Belum terwakili") -> 4 | L32: =SUMIFS(Data_HS!$D$2:$D$8217,Data_HS!$F$2:$F$8217,A32,Data_HS!$I$2:$I$8217,"Belum terwakili")/10^9 -> 4.667153 | M32: =SUMIFS(Data_Eksportir!$N$2:$N$3401,Data_Eksportir!$O$2:$O$3401,A32,Data_Eksportir!$Q$2:$Q$3401,"Wajar")/10^6 -> 0.025444443 | N32: =E32+ROW()/10^9 -> 4.6904165 | O32: =L32+ROW()/10^9 -> 4.6671531
A33: 27 | B33: Batubara, migas & bahan bakar | C33: =COUNTIFS(Data_HS!$F$2:$F$8217,A33,Data_HS!$D$2:$D$8217,">0") -> 53 | D33: =SUMIFS(Data_HS!$C$2:$C$8217,Data_HS!$F$2:$F$8217,A33)/10^9 -> 91.808234 | E33: =SUMIFS(Data_HS!$D$2:$D$8217,Data_HS!$F$2:$F$8217,A33)/10^9 -> 23.823585 | F33: =E33/$E$105 -> 0.101537 | G33: =IFERROR(SUMIFS(Data_HS!$D$2:$D$8217,Data_HS!$F$2:$F$8217,A33,Data_HS!$C$2:$C$8217,">0")/SUMIFS(Data_HS!$C$2:$C$8217,Data_HS!$F$2:$F$8217,A33),"") -> 0.20447042 | H33: =COUNTIF(Data_Eksportir!$O$2:$O$3401,A33) -> 33 | I33: =IF(A33=0,"",H33/COUNTIF(Data_Eksportir!$O$2:$O$3401,">0")) -> 0.010669253 | J33: =IF(OR(A33=0,F33=0),"",I33/F33) -> 0.10507749 | K33: =COUNTIFS(Data_HS!$F$2:$F$8217,A33,Data_HS!$I$2:$I$8217,"Belum terwakili") -> 22 | L33: =SUMIFS(Data_HS!$D$2:$D$8217,Data_HS!$F$2:$F$8217,A33,Data_HS!$I$2:$I$8217,"Belum terwakili")/10^9 -> 21.471178 | M33: =SUMIFS(Data_Eksportir!$N$2:$N$3401,Data_Eksportir!$O$2:$O$3401,A33,Data_Eksportir!$Q$2:$Q$3401,"Wajar")/10^6 -> 36.307329 | N33: =E33+ROW()/10^9 -> 23.823585 | O33: =L33+ROW()/10^9 -> 21.471178
A34: 28 | B34: Kimia anorganik | C34: =COUNTIFS(Data_HS!$F$2:$F$8217,A34,Data_HS!$D$2:$D$8217,">0") -> 127 | D34: =SUMIFS(Data_HS!$C$2:$C$8217,Data_HS!$F$2:$F$8217,A34)/10^9 -> 6.8996891 | E34: =SUMIFS(Data_HS!$D$2:$D$8217,Data_HS!$F$2:$F$8217,A34)/10^9 -> 4.1171817 | F34: =E34/$E$105 -> 0.01754758 | G34: =IFERROR(SUMIFS(Data_HS!$D$2:$D$8217,Data_HS!$F$2:$F$8217,A34,Data_HS!$C$2:$C$8217,">0")/SUMIFS(Data_HS!$C$2:$C$8217,Data_HS!$F$2:$F$8217,A34),"") -> 0.59671988 | H34: =COUNTIF(Data_Eksportir!$O$2:$O$3401,A34) -> 6 | I34: =IF(A34=0,"",H34/COUNTIF(Data_Eksportir!$O$2:$O$3401,">0")) -> 0.0019398642 | J34: =IF(OR(A34=0,F34=0),"",I34/F34) -> 0.11054882 | K34: =COUNTIFS(Data_HS!$F$2:$F$8217,A34,Data_HS!$I$2:$I$8217,"Belum terwakili") -> 16 | L34: =SUMIFS(Data_HS!$D$2:$D$8217,Data_HS!$F$2:$F$8217,A34,Data_HS!$I$2:$I$8217,"Belum terwakili")/10^9 -> 3.7680205 | M34: =SUMIFS(Data_Eksportir!$N$2:$N$3401,Data_Eksportir!$O$2:$O$3401,A34,Data_Eksportir!$Q$2:$Q$3401,"Wajar")/10^6 -> 0.001398722 | N34: =E34+ROW()/10^9 -> 4.1171817 | O34: =L34+ROW()/10^9 -> 3.7680206
A35: 29 | B35: Kimia organik | C35: =COUNTIFS(Data_HS!$F$2:$F$8217,A35,Data_HS!$D$2:$D$8217,">0") -> 278 | D35: =SUMIFS(Data_HS!$C$2:$C$8217,Data_HS!$F$2:$F$8217,A35)/10^9 -> 3.7068386 | E35: =SUMIFS(Data_HS!$D$2:$D$8217,Data_HS!$F$2:$F$8217,A35)/10^9 -> 3.965024 | F35: =E35/$E$105 -> 0.016899078 | G35: =IFERROR(SUMIFS(Data_HS!$D$2:$D$8217,Data_HS!$F$2:$F$8217,A35,Data_HS!$C$2:$C$8217,">0")/SUMIFS(Data_HS!$C$2:$C$8217,Data_HS!$F$2:$F$8217,A35),"") -> 1.0696509 | H35: =COUNTIF(Data_Eksportir!$O$2:$O$3401,A35) -> 3 | I35: =IF(A35=0,"",H35/COUNTIF(Data_Eksportir!$O$2:$O$3401,">0")) -> 0.0009699321 | J35: =IF(OR(A35=0,F35=0),"",I35/F35) -> 0.057395563 | K35: =COUNTIFS(Data_HS!$F$2:$F$8217,A35,Data_HS!$I$2:$I$8217,"Belum terwakili") -> 38 | L35: =SUMIFS(Data_HS!$D$2:$D$8217,Data_HS!$F$2:$F$8217,A35,Data_HS!$I$2:$I$8217,"Belum terwakili")/10^9 -> 3.8425245 | M35: =SUMIFS(Data_Eksportir!$N$2:$N$3401,Data_Eksportir!$O$2:$O$3401,A35,Data_Eksportir!$Q$2:$Q$3401,"Wajar")/10^6 -> 0 | N35: =E35+ROW()/10^9 -> 3.9650241 | O35: =L35+ROW()/10^9 -> 3.8425246
A36: 30 | B36: Farmasi | C36: =COUNTIFS(Data_HS!$F$2:$F$8217,A36,Data_HS!$D$2:$D$8217,">0") -> 86 | D36: =SUMIFS(Data_HS!$C$2:$C$8217,Data_HS!$F$2:$F$8217,A36)/10^9 -> 0.023487927 | E36: =SUMIFS(Data_HS!$D$2:$D$8217,Data_HS!$F$2:$F$8217,A36)/10^9 -> 0.68423699 | F36: =E36/$E$105 -> 0.0029162432 | G36: =IFERROR(SUMIFS(Data_HS!$D$2:$D$8217,Data_HS!$F$2:$F$8217,A36,Data_HS!$C$2:$C$8217,">0")/SUMIFS(Data_HS!$C$2:$C$8217,Data_HS!$F$2:$F$8217,A36),"") -> 29.131417 | H36: =COUNTIF(Data_Eksportir!$O$2:$O$3401,A36) -> 6 | I36: =IF(A36=0,"",H36/COUNTIF(Data_Eksportir!$O$2:$O$3401,">0")) -> 0.0019398642 | J36: =IF(OR(A36=0,F36=0),"",I36/F36) -> 0.66519288 | K36: =COUNTIFS(Data_HS!$F$2:$F$8217,A36,Data_HS!$I$2:$I$8217,"Belum terwakili") -> 13 | L36: =SUMIFS(Data_HS!$D$2:$D$8217,Data_HS!$F$2:$F$8217,A36,Data_HS!$I$2:$I$8217,"Belum terwakili")/10^9 -> 0.59631306 | M36: =SUMIFS(Data_Eksportir!$N$2:$N$3401,Data_Eksportir!$O$2:$O$3401,A36,Data_Eksportir!$Q$2:$Q$3401,"Wajar")/10^6 -> 0 | N36: =E36+ROW()/10^9 -> 0.68423703 | O36: =L36+ROW()/10^9 -> 0.59631309
A37: 31 | B37: Pupuk | C37: =COUNTIFS(Data_HS!$F$2:$F$8217,A37,Data_HS!$D$2:$D$8217,">0") -> 23 | D37: =SUMIFS(Data_HS!$C$2:$C$8217,Data_HS!$F$2:$F$8217,A37)/10^9 -> 1.9069557 | E37: =SUMIFS(Data_HS!$D$2:$D$8217,Data_HS!$F$2:$F$8217,A37)/10^9 -> 0.76641507 | F37: =E37/$E$105 -> 0.0032664892 | G37: =IFERROR(SUMIFS(Data_HS!$D$2:$D$8217,Data_HS!$F$2:$F$8217,A37,Data_HS!$C$2:$C$8217,">0")/SUMIFS(Data_HS!$C$2:$C$8217,Data_HS!$F$2:$F$8217,A37),"") -> 0.40190503 | H37: =COUNTIF(Data_Eksportir!$O$2:$O$3401,A37) -> 11 | I37: =IF(A37=0,"",H37/COUNTIF(Data_Eksportir!$O$2:$O$3401,">0")) -> 0.0035564177 | J37: =IF(OR(A37=0,F37=0),"",I37/F37) -> 1.0887585 | K37: =COUNTIFS(Data_HS!$F$2:$F$8217,A37,Data_HS!$I$2:$I$8217,"Belum terwakili") -> 4 | L37: =SUMIFS(Data_HS!$D$2:$D$8217,Data_HS!$F$2:$F$8217,A37,Data_HS!$I$2:$I$8217,"Belum terwakili")/10^9 -> 0.73318268 | M37: =SUMIFS(Data_Eksportir!$N$2:$N$3401,Data_Eksportir!$O$2:$O$3401,A37,Data_Eksportir!$Q$2:$Q$3401,"Wajar")/10^6 -> 0.35003501 | N37: =E37+ROW()/10^9 -> 0.76641511 | O37: =L37+ROW()/10^9 -> 0.73318272
A38: 32 | B38: Pewarna, cat & pernis | C38: =COUNTIFS(Data_HS!$F$2:$F$8217,A38,Data_HS!$D$2:$D$8217,">0") -> 73 | D38: =SUMIFS(Data_HS!$C$2:$C$8217,Data_HS!$F$2:$F$8217,A38)/10^9 -> 0.13728833 | E38: =SUMIFS(Data_HS!$D$2:$D$8217,Data_HS!$F$2:$F$8217,A38)/10^9 -> 0.41810061 | F38: =E38/$E$105 -> 0.0017819601 | G38: =IFERROR(SUMIFS(Data_HS!$D$2:$D$8217,Data_HS!$F$2:$F$8217,A38,Data_HS!$C$2:$C$8217,">0")/SUMIFS(Data_HS!$C$2:$C$8217,Data_HS!$F$2:$F$8217,A38),"") -> 3.0454185 | H38: =COUNTIF(Data_Eksportir!$O$2:$O$3401,A38) -> 16 | I38: =IF(A38=0,"",H38/COUNTIF(Data_Eksportir!$O$2:$O$3401,">0")) -> 0.0051729712 | J38: =IF(OR(A38=0,F38=0),"",I38/F38) -> 2.9029669 | K38: =COUNTIFS(Data_HS!$F$2:$F$8217,A38,Data_HS!$I$2:$I$8217,"Belum terwakili") -> 10 | L38: =SUMIFS(Data_HS!$D$2:$D$8217,Data_HS!$F$2:$F$8217,A38,Data_HS!$I$2:$I$8217,"Belum terwakili")/10^9 -> 0.27531779 | M38: =SUMIFS(Data_Eksportir!$N$2:$N$3401,Data_Eksportir!$O$2:$O$3401,A38,Data_Eksportir!$Q$2:$Q$3401,"Wajar")/10^6 -> 0.45161774 | N38: =E38+ROW()/10^9 -> 0.41810064 | O38: =L38+ROW()/10^9 -> 0.27531783
A39: 33 | B39: Minyak atsiri & kosmetik | C39: =COUNTIFS(Data_HS!$F$2:$F$8217,A39,Data_HS!$D$2:$D$8217,">0") -> 50 | D39: =SUMIFS(Data_HS!$C$2:$C$8217,Data_HS!$F$2:$F$8217,A39)/10^9 -> 0.13001755 | E39: =SUMIFS(Data_HS!$D$2:$D$8217,Data_HS!$F$2:$F$8217,A39)/10^9 -> 1.0498032 | F39: =E39/$E$105 -> 0.0044742996 | G39: =IFERROR(SUMIFS(Data_HS!$D$2:$D$8217,Data_HS!$F$2:$F$8217,A39,Data_HS!$C$2:$C$8217,">0")/SUMIFS(Data_HS!$C$2:$C$8217,Data_HS!$F$2:$F$8217,A39),"") -> 8.0743192 | H39: =COUNTIF(Data_Eksportir!$O$2:$O$3401,A39) -> 49 | I39: =IF(A39=0,"",H39/COUNTIF(Data_Eksportir!$O$2:$O$3401,">0")) -> 0.015842224 | J39: =IF(OR(A39=0,F39=0),"",I39/F39) -> 3.540716 | K39: =COUNTIFS(Data_HS!$F$2:$F$8217,A39,Data_HS!$I$2:$I$8217,"Belum terwakili") -> 14 | L39: =SUMIFS(Data_HS!$D$2:$D$8217,Data_HS!$F$2:$F$8217,A39,Data_HS!$I$2:$I$8217,"Belum terwakili")/10^9 -> 0.70894141 | M39: =SUMIFS(Data_Eksportir!$N$2:$N$3401,Data_Eksportir!$O$2:$O$3401,A39,Data_Eksportir!$Q$2:$Q$3401,"Wajar")/10^6 -> 3.6100428 | N39: =E39+ROW()/10^9 -> 1.0498032 | O39: =L39+ROW()/10^9 -> 0.70894145
